Workbook

Sheet MENU
B1: PAINEL DE CONTAS A RECEBER VENCIDO | F1: TT VENCIDO => | H1: =SUM(H2:H4) -> 24967.61 | L1: META | M1: REAL | N1: FATURAMENTO MÊS | O1: CLASSIFICAÇÃO | Q1: RESPONSABILIDADE
F2: R$ INAD. => | H2: =SUMIFS(O:O,B:B,"INAD.",K:K,">=-30",K:K,"<=0") -> 14988.2 | L2: 0.00301 | M2: =IFERROR(H2/N2,"-") -> 0.003771456 | N2: 3974115 | O2: INAD. | P2: ATÉ 30d. | Q2: RN | R2: ATÉ 15d.
C3: UNIDADE: | D3: CRUZ | F3: R$ IREC. => | H3: =SUMIFS(O:O,B:B,"IREC.",K:K,">=-75",K:K,"<=0") -> 8586.94 | O3: IREC. | P3: ATÉ 75d. | Q3: GV | R3: ATÉ 45d.
C4: MÊS: | D4: 46113 | F4: R$ PDD => | H4: =SUMIFS(O:O, B:B, "PDD", K:K, "<=-75") -> 1392.47 | L4: 0.12% | M4: =IFERROR(H3/N2,"-") -> 0.0021607175 | O4: PDD | P4: ACIMA 75d. | Q4: GC | R4: ACIMA 45d.
A7: Validador | B7: STATUS | C7: DONO | D7: CLIENTE | E7: NOME | F7: UNB | G7: TITULO | H7: RN | I7: NOME DO RN | J7: NOME DO GC/GV | K7: DIAS | L7: EMISSÃO | M7: ENTREGA | N7: VENC.TO | O7: VALOR | P7: PENDENTE | Q7: CORRIGIDO | R7: Nr. BANCO | T7: DATA | U7: AÇÃO
A8: ='CAR PROMAX FILIAL CRUZ'!O2 -> -95 | B8: =IF(K8<0,IF(K8>-31,"INAD.",IF(K8>-76,"IREC.","PDD"))," ") -> PDD | C8: =IF(K8<0,IF(K8>-16,"RN",IF(K8>-46,"GV","GC"))," ") -> GC | D8: =IF(A8<0,'CAR PROMAX FILIAL CRUZ'!B2," ") -> 576 | E8: =IF(A8<0,'CAR PROMAX FILIAL CRUZ'!C2," ") -> ROCK VARIEDADES JUR | F8: =IF(A8<0,'CAR PROMAX FILIAL CRUZ'!D2," ") -> 2 | G8: =IF(A8<0,'CAR PROMAX FILIAL CRUZ'!E2," ") -> 79246 | H8: =IF(A8<0,'CAR PROMAX FILIAL CRUZ'!J2," ") -> 101 | I8: =_xlfn.XLOOKUP(H8,'RN - SETORES'!A:A,'RN - SETORES'!B:B) -> Francisco Damilo | J8: =_xlfn.XLOOKUP(C8,'GV - SETORES'!D:D,'GV - SETORES'!E:E,IF(K8>=-45,_xlfn.XLOOKUP(H8,'GV - SETORES'!A:A,'GV - SETORES'!B:B))) -> Anderson | K8: =IF(A8<0,'CAR PROMAX FILIAL CRUZ'!O2," ") -> -95 | L8: =IF(A8<0,'CAR PROMAX FILIAL CRUZ'!P2," ") -> 46034 | M8: =IF(A8<0,'CAR PROMAX FILIAL CRUZ'!Q2," ") -> 46035 | N8: =IF(A8<0,'CAR PROMAX FILIAL CRUZ'!R2," ") -> 46041 | O8: =IF(A8<0,'CAR PROMAX FILIAL CRUZ'!S2," ") -> 459.85 | P8: =IF(A8<0,'CAR PROMAX FILIAL CRUZ'!T2," ") -> 459.85 | Q8: =IF(A8<0,'CAR PROMAX FILIAL CRUZ'!U2," ") -> 555.18 | R8: =IF(A8<0,'CAR PROMAX FILIAL CRUZ'!V2," ") -> 3612006755
A9: ='CAR PROMAX FILIAL CRUZ'!O3 -> -93 | B9: =IF(K9<0,IF(K9>-31,"INAD.",IF(K9>-76,"IREC.","PDD"))," ") -> PDD | C9: =IF(K9<0,IF(K9>-16,"RN",IF(K9>-46,"GV","GC"))," ") -> GC | D9: =IF(A9<0,'CAR PROMAX FILIAL CRUZ'!B3," ") -> 3730 | E9: =IF(A9<0,'CAR PROMAX FILIAL CRUZ'!C3," ") -> GELADAO PREA | F9: =IF(A9<0,'CAR PROMAX FILIAL CRUZ'!D3," ") -> 2 | G9: =IF(A9<0,'CAR PROMAX FILIAL CRUZ'!E3," ") -> 79463 | H9: =IF(A9<0,'CAR PROMAX FILIAL CRUZ'!J3," ") -> 514 | I9: =_xlfn.XLOOKUP(H9,'RN - SETORES'!A:A,'RN - SETORES'!B:B) -> Juan | J9: =_xlfn.XLOOKUP(C9,'GV - SETORES'!D:D,'GV - SETORES'!E:E,IF(K9>=-45,_xlfn.XLOOKUP(H9,'GV - SETORES'!A:A,'GV - SETORES'!B:B))) -> Anderson | K9: =IF(A9<0,'CAR PROMAX FILIAL CRUZ'!O3," ") -> -93 | L9: =IF(A9<0,'CAR PROMAX FILIAL CRUZ'!P3," ") -> 46035 | M9: =IF(A9<0,'CAR PROMAX FILIAL CRUZ'!Q3," ") -> 46036 | N9: =IF(A9<0,'CAR PROMAX FILIAL CRUZ'!R3," ") -> 46043 | O9: =IF(A9<0,'CAR PROMAX FILIAL CRUZ'!S3," ") -> 631.69 | P9: =IF(A9<0,'CAR PROMAX FILIAL CRUZ'!T3," ") -> 631.69 | Q9: =IF(A9<0,'CAR PROMAX FILIAL CRUZ'!U3," ") -> 760.55 | R9: =IF(A9<0,'CAR PROMAX FILIAL CRUZ'!V3," ") -> 3612006784
A10: ='CAR PROMAX FILIAL CRUZ'!O4 -> -88 | B10: =IF(K10<0,IF(K10>-31,"INAD.",IF(K10>-76,"IREC.","PDD"))," ") -> PDD | C10: =IF(K10<0,IF(K10>-16,"RN",IF(K10>-46,"GV","GC"))," ") -> GC | D10: =IF(A10<0,'CAR PROMAX FILIAL CRUZ'!B4," ") -> 576 | E10: =IF(A10<0,'CAR PROMAX FILIAL CRUZ'!C4," ") -> ROCK VARIEDADES JUR | F10: =IF(A10<0,'CAR PROMAX FILIAL CRUZ'!D4," ") -> 2 | G10: =IF(A10<0,'CAR PROMAX FILIAL CRUZ'!E4," ") -> 80550 | H10: =IF(A10<0,'CAR PROMAX FILIAL CRUZ'!J4," ") -> 101 | I10: =_xlfn.XLOOKUP(H10,'RN - SETORES'!A:A,'RN - SETORES'!B:B) -> Francisco Damilo | J10: =_xlfn.XLOOKUP(C10,'GV - SETORES'!D:D,'GV - SETORES'!E:E,IF(K10>=-45,_xlfn.XLOOKUP(H10,'GV - SETORES'!A:A,'GV - SETORES'!B:B))) -> Anderson | K10: =IF(A10<0,'CAR PROMAX FILIAL CRUZ'!O4," ") -> -88 | L10: =IF(A10<0,'CAR PROMAX FILIAL CRUZ'!P4," ") -> 46041 | M10: =IF(A10<0,'CAR PROMAX FILIAL CRUZ'!Q4," ") -> 46042 | N10: =IF(A10<0,'CAR PROMAX FILIAL CRUZ'!R4," ") -> 46048 | O10: =IF(A10<0,'CAR PROMAX FILIAL CRUZ'!S4," ") -> 300.93 | P10: =IF(A10<0,'CAR PROMAX FILIAL CRUZ'!T4," ") -> 300.93 | Q10: =IF(A10<0,'CAR PROMAX FILIAL CRUZ'!U4," ") -> 359.8 | R10: =IF(A10<0,'CAR PROMAX FILIAL CRUZ'!V4," ") -> 3612006964
A11: ='CAR PROMAX FILIAL CRUZ'!O5 -> -74 | B11: =IF(K11<0,IF(K11>-31,"INAD.",IF(K11>-76,"IREC.","PDD"))," ") -> IREC. | C11: =IF(K11<0,IF(K11>-16,"RN",IF(K11>-46,"GV","GC"))," ") -> GC | D11: =IF(A11<0,'CAR PROMAX FILIAL CRUZ'!B5," ") -> 253 | E11: =IF(A11<0,'CAR PROMAX FILIAL CRUZ'!C5," ") -> PESQUE E PAGUE SAO J | F11: =IF(A11<0,'CAR PROMAX FILIAL CRUZ'!D5," ") -> 2 | G11: =IF(A11<0,'CAR PROMAX FILIAL CRUZ'!E5," ") -> 83008 | H11: =IF(A11<0,'CAR PROMAX FILIAL CRUZ'!J5," ") -> 513 | I11: =_xlfn.XLOOKUP(H11,'RN - SETORES'!A:A,'RN - SETORES'!B:B) -> Jefferson | J11: =_xlfn.XLOOKUP(C11,'GV - SETORES'!D:D,'GV - SETORES'!E:E,IF(K11>=-45,_xlfn.XLOOKUP(H11,'GV - SETORES'!A:A,'GV - SETORES'!B:B))) -> Anderson | K11: =IF(A11<0,'CAR PROMAX FILIAL CRUZ'!O5," ") -> -74 | L11: =IF(A11<0,'CAR PROMAX FILIAL CRUZ'!P5," ") -> 46052 | M11: =IF(A11<0,'CAR PROMAX FILIAL CRUZ'!Q5," ") -> 46053 | N11: =IF(A11<0,'CAR PROMAX FILIAL CRUZ'!R5," ") -> 46062 | O11: =IF(A11<0,'CAR PROMAX FILIAL CRUZ'!S5," ") -> 143.31 | P11: =IF(A11<0,'CAR PROMAX FILIAL CRUZ'!T5," ") -> 143.31 | Q11: =IF(A11<0,'CAR PROMAX FILIAL CRUZ'!U5," ") -> 168 | R11: =IF(A11<0,'CAR PROMAX FILIAL CRUZ'!V5," ") -> 3612007292
A12: ='CAR PROMAX FILIAL CRUZ'!O6 -> -74 | B12: =IF(K12<0,IF(K12>-31,"INAD.",IF(K12>-76,"IREC.","PDD"))," ") -> IREC. | C12: =IF(K12<0,IF(K12>-16,"RN",IF(K12>-46,"GV","GC"))," ") -> GC | D12: =IF(A12<0,'CAR PROMAX FILIAL CRUZ'!B6," ") -> 253 | E12: =IF(A12<0,'CAR PROMAX FILIAL CRUZ'!C6," ") -> PESQUE E PAGUE SAO J | F12: =IF(A12<0,'CAR PROMAX FILIAL CRUZ'!D6," ") -> 2 | G12: =IF(A12<0,'CAR PROMAX FILIAL CRUZ'!E6," ") -> 83009 | H12: =IF(A12<0,'CAR PROMAX FILIAL CRUZ'!J6," ") -> 513 | I12: =_xlfn.XLOOKUP(H12,'RN - SETORES'!A:A,'RN - SETORES'!B:B) -> Jefferson | J12: =_xlfn.XLOOKUP(C12,'GV - SETORES'!D:D,'GV - SETORES'!E:E,IF(K12>=-45,_xlfn.XLOOKUP(H12,'GV - SETORES'!A:A,'GV - SETORES'!B:B))) -> Anderson | K12: =IF(A12<0,'CAR PROMAX FILIAL CRUZ'!O6," ") -> -74 | L12: =IF(A12<0,'CAR PROMAX FILIAL CRUZ'!P6," ") -> 46052 | M12: =IF(A12<0,'CAR PROMAX FILIAL CRUZ'!Q6," ") -> 46053 | N12: =IF(A12<0,'CAR PROMAX FILIAL CRUZ'!R6," ") -> 46062 | O12: =IF(A12<0,'CAR PROMAX FILIAL CRUZ'!S6," ") -> 883.83 | P12: =IF(A12<0,'CAR PROMAX FILIAL CRUZ'!T6," ") -> 883.83 | Q12: =IF(A12<0,'CAR PROMAX FILIAL CRUZ'!U6," ") -> 1036.13 | R12: =IF(A12<0,'CAR PROMAX FILIAL CRUZ'!V6," ") -> 3612007293
A13: ='CAR PROMAX FILIAL CRUZ'!O7 -> -67 | B13: =IF(K13<0,IF(K13>-31,"INAD.",IF(K13>-76,"IREC.","PDD"))," ") -> IREC. | C13: =IF(K13<0,IF(K13>-16,"RN",IF(K13>-46,"GV","GC"))," ") -> GC | D13: =IF(A13<0,'CAR PROMAX FILIAL CRUZ'!B7," ") -> 253 | E13: =IF(A13<0,'CAR PROMAX FILIAL CRUZ'!C7," ") -> PESQUE E PAGUE SAO J | F13: =IF(A13<0,'CAR PROMAX FILIAL CRUZ'!D7," ") -> 2 | G13: =IF(A13<0,'CAR PROMAX FILIAL CRUZ'!E7," ") -> 84202 | H13: =IF(A13<0,'CAR PROMAX FILIAL CRUZ'!J7," ") -> 513 | I13: =_xlfn.XLOOKUP(H13,'RN - SETORES'!A:A,'RN - SETORES'!B:B) -> Jefferson | J13: =_xlfn.XLOOKUP(C13,'GV - SETORES'!D:D,'GV - SETORES'!E:E,IF(K13>=-45,_xlfn.XLOOKUP(H13,'GV - SETORES'!A:A,'GV - SETORES'!B:B))) -> Anderson | K13: =IF(A13<0,'CAR PROMAX FILIAL CRUZ'!O7," ") -> -67 | L13: =IF(A13<0,'CAR PROMAX FILIAL CRUZ'!P7," ") -> 46059 | M13: =IF(A13<0,'CAR PROMAX FILIAL CRUZ'!Q7," ") -> 46060 | N13: =IF(A13<0,'CAR PROMAX FILIAL CRUZ'!R7," ") -> 46069 | O13: =IF(A13<0,'CAR PROMAX FILIAL CRUZ'!S7," ") -> 827.03 | P13: =IF(A13<0,'CAR PROMAX FILIAL CRUZ'!T7," ") -> 827.03 | Q13: =IF(A13<0,'CAR PROMAX FILIAL CRUZ'!U7," ") -> 959.9 | R13: =IF(A13<0,'CAR PROMAX FILIAL CRUZ'!V7," ") -> 3612007481
A14: ='CAR PROMAX FILIAL CRUZ'!O8 -> -65 | B14: =IF(K14<0,IF(K14>-31,"INAD.",IF(K14>-76,"IREC.","PDD"))," ") -> IREC. | C14: =IF(K14<0,IF(K14>-16,"RN",IF(K14>-46,"GV","GC"))," ") -> GC | D14: =IF(A14<0,'CAR PROMAX FILIAL CRUZ'!B8," ") -> 3898 | E14: =IF(A14<0,'CAR PROMAX FILIAL CRUZ'!C8," ") -> ROTA DO SABOR | F14: =IF(A14<0,'CAR PROMAX FILIAL CRUZ'!D8," ") -> 2 | G14: =IF(A14<0,'CAR PROMAX FILIAL CRUZ'!E8," ") -> 85694 | H14: =IF(A14<0,'CAR PROMAX FILIAL CRUZ'!J8," ") -> 104 | I14: =_xlfn.XLOOKUP(H14,'RN - SETORES'!A:A,'RN - SETORES'!B:B) -> Neto | J14: =_xlfn.XLOOKUP(C14,'GV - SETORES'!D:D,'GV - SETORES'!E:E,IF(K14>=-45,_xlfn.XLOOKUP(H14,'GV - SETORES'!A:A,'GV - SETORES'!B:B))) -> Anderson | K14: =IF(A14<0,'CAR PROMAX FILIAL CRUZ'!O8," ") -> -65 | L14: =IF(A14<0,'CAR PROMAX FILIAL CRUZ'!P8," ") -> 46066 | M14: =IF(A14<0,'CAR PROMAX FILIAL CRUZ'!Q8," ") -> 46067 | N14: =IF(A14<0,'CAR PROMAX FILIAL CRUZ'!R8," ") -> 46071 | O14: =IF(A14<0,'CAR PROMAX FILIAL CRUZ'!S8," ") -> 213.61 | P14: =IF(A14<0,'CAR PROMAX FILIAL CRUZ'!T8," ") -> 213.61 | Q14: =IF(A14<0,'CAR PROMAX FILIAL CRUZ'!U8," ") -> 247.21 | R14: =IF(A14<0,'CAR PROMAX FILIAL CRUZ'!V8," ") -> 3612007713
A15: ='CAR PROMAX FILIAL CRUZ'!O9 -> -56 | B15: =IF(K15<0,IF(K15>-31,"INAD.",IF(K15>-76,"IREC.","PDD"))," ") -> IREC. | C15: =IF(K15<0,IF(K15>-16,"RN",IF(K15>-46,"GV","GC"))," ") -> GC | D15: =IF(A15<0,'CAR PROMAX FILIAL CRUZ'!B9," ") -> 3581 | E15: =IF(A15<0,'CAR PROMAX FILIAL CRUZ'!C9," ") -> ADEGA BAR | F15: =IF(A15<0,'CAR PROMAX FILIAL CRUZ'!D9," ") -> 2 | G15: =IF(A15<0,'CAR PROMAX FILIAL CRUZ'!E9," ") -> 86353 | H15: =IF(A15<0,'CAR PROMAX FILIAL CRUZ'!J9," ") -> 102 | I15: =_xlfn.XLOOKUP(H15,'RN - SETORES'!A:A,'RN - SETORES'!B:B) -> Francisco | J15: =_xlfn.XLOOKUP(C15,'GV - SETORES'!D:D,'GV - SETORES'!E:E,IF(K15>=-45,_xlfn.XLOOKUP(H15,'GV - SETORES'!A:A,'GV - SETORES'!B:B))) -> Anderson | K15: =IF(A15<0,'CAR PROMAX FILIAL CRUZ'!O9," ") -> -56 | L15: =IF(A15<0,'CAR PROMAX FILIAL CRUZ'!P9," ") -> 46072 | M15: =IF(A15<0,'CAR PROMAX FILIAL CRUZ'!Q9," ") -> 46073 | N15: =IF(A15<0,'CAR PROMAX FILIAL CRUZ'!R9," ") -> 46080 | O15: =IF(A15<0,'CAR PROMAX FILIAL CRUZ'!S9," ") -> 392.88 | P15: =IF(A15<0,'CAR PROMAX FILIAL CRUZ'!T9," ") -> 392.88 | Q15: =IF(A15<0,'CAR PROMAX FILIAL CRUZ'!U9," ") -> 448.79 | R15: =IF(A15<0,'CAR PROMAX FILIAL CRUZ'!V9," ") -> 3612007801
A16: ='CAR PROMAX FILIAL CRUZ'!O10 -> -56 | B16: =IF(K16<0,IF(K16>-31,"INAD.",IF(K16>-76,"IREC.","PDD"))," ") -> IREC. | C16: =IF(K16<0,IF(K16>-16,"RN",IF(K16>-46,"GV","GC"))," ") -> GC | D16: =IF(A16<0,'CAR PROMAX FILIAL CRUZ'!B10," ") -> 3581 | E16: =IF(A16<0,'CAR PROMAX FILIAL CRUZ'!C10," ") -> ADEGA BAR | F16: =IF(A16<0,'CAR PROMAX FILIAL CRUZ'!D10," ") -> 2 | G16: =IF(A16<0,'CAR PROMAX FILIAL CRUZ'!E10," ") -> 86354 | H16: =IF(A16<0,'CAR PROMAX FILIAL CRUZ'!J10," ") -> 102 | I16: =_xlfn.XLOOKUP(H16,'RN - SETORES'!A:A,'RN - SETORES'!B:B) -> Francisco | J16: =_xlfn.XLOOKUP(C16,'GV - SETORES'!D:D,'GV - SETORES'!E:E,IF(K16>=-45,_xlfn.XLOOKUP(H16,'GV - SETORES'!A:A,'GV - SETORES'!B:B))) -> Anderson | K16: =IF(A16<0,'CAR PROMAX FILIAL CRUZ'!O10," ") -> -56 | L16: =IF(A16<0,'CAR PROMAX FILIAL CRUZ'!P10," ") -> 46072 | M16: =IF(A16<0,'CAR PROMAX FILIAL CRUZ'!Q10," ") -> 46073 | N16: =IF(A16<0,'CAR PROMAX FILIAL CRUZ'!R10," ") -> 46080 | O16: =IF(A16<0,'CAR PROMAX FILIAL CRUZ'!S10," ") -> 509.94 | P16: =IF(A16<0,'CAR PROMAX FILIAL CRUZ'!T10," ") -> 509.94 | Q16: =IF(A16<0,'CAR PROMAX FILIAL CRUZ'!U10," ") -> 582.51 | R16: =IF(A16<0,'CAR PROMAX FILIAL CRUZ'!V10," ") -> 3612007802
A17: ='CAR PROMAX FILIAL CRUZ'!O11 -> -52 | B17: =IF(K17<0,IF(K17>-31,"INAD.",IF(K17>-76,"IREC.","PDD"))," ") -> IREC. | C17: =IF(K17<0,IF(K17>-16,"RN",IF(K17>-46,"GV","GC"))," ") -> GC | D17: =IF(A17<0,'CAR PROMAX FILIAL CRUZ'!B11," ") -> 2977 | E17: =IF(A17<0,'CAR PROMAX FILIAL CRUZ'!C11," ") -> TRE CRAZY | F17: =IF(A17<0,'CAR PROMAX FILIAL CRUZ'!D11," ") -> 2 | G17: =IF(A17<0,'CAR PROMAX FILIAL CRUZ'!E11," ") -> 86678 | H17: =IF(A17<0,'CAR PROMAX FILIAL CRUZ'!J11," ") -> 515 | I17: =_xlfn.XLOOKUP(H17,'RN - SETORES'!A:A,'RN - SETORES'!B:B) -> Jose | J17: =_xlfn.XLOOKUP(C17,'GV - SETORES'!D:D,'GV - SETORES'!E:E,IF(K17>=-45,_xlfn.XLOOKUP(H17,'GV - SETORES'!A:A,'GV - SETORES'!B:B))) -> Anderson | K17: =IF(A17<0,'CAR PROMAX FILIAL CRUZ'!O11," ") -> -52 | L17: =IF(A17<0,'CAR PROMAX FILIAL CRUZ'!P11," ") -> 46076 | M17: =IF(A17<0,'CAR PROMAX FILIAL CRUZ'!Q11," ") -> 46077 | N17: =IF(A17<0,'CAR PROMAX FILIAL CRUZ'!R11," ") -> 46084 | O17: =IF(A17<0,'CAR PROMAX FILIAL CRUZ'!S11," ") -> 900.3 | P17: =IF(A17<0,'CAR PROMAX FILIAL CRUZ'!T11," ") -> 900.3 | Q17: =IF(A17<0,'CAR PROMAX FILIAL CRUZ'!U11," ") -> 1022.43 | R17: =IF(A17<0,'CAR PROMAX FILIAL CRUZ'!V11," ") -> 3612007844
A18: ='CAR PROMAX FILIAL CRUZ'!O12 -> -44 | B18: =IF(K18<0,IF(K18>-31,"INAD.",IF(K18>-76,"IREC.","PDD"))," ") -> IREC. | C18: =IF(K18<0,IF(K18>-16,"RN",IF(K18>-46,"GV","GC"))," ") -> GV | D18: =IF(A18<0,'CAR PROMAX FILIAL CRUZ'!B12," ") -> 3322 | E18: =IF(A18<0,'CAR PROMAX FILIAL CRUZ'!C12," ") -> PIZZARIA O ZEZINHO | F18: =IF(A18<0,'CAR PROMAX FILIAL CRUZ'!D12," ") -> 2 | G18: =IF(A18<0,'CAR PROMAX FILIAL CRUZ'!E12," ") -> 88274 | H18: =IF(A18<0,'CAR PROMAX FILIAL CRUZ'!J12," ") -> 101 | I18: =_xlfn.XLOOKUP(H18,'RN - SETORES'!A:A,'RN - SETORES'!B:B) -> Francisco Damilo | J18: =_xlfn.XLOOKUP(C18,'GV - SETORES'!D:D,'GV - SETORES'!E:E,IF(K18>=-45,_xlfn.XLOOKUP(H18,'GV - SETORES'!A:A,'GV - SETORES'!B:B))) -> Fredson | K18: =IF(A18<0,'CAR PROMAX FILIAL CRUZ'!O12," ") -> -44 | L18: =IF(A18<0,'CAR PROMAX FILIAL CRUZ'!P12," ") -> 46084 | M18: =IF(A18<0,'CAR PROMAX FILIAL CRUZ'!Q12," ") -> 46085 | N18: =IF(A18<0,'CAR PROMAX FILIAL CRUZ'!R12," ") -> 46092 | O18: =IF(A18<0,'CAR PROMAX FILIAL CRUZ'!S12," ") -> 304.13 | P18: =IF(A18<0,'CAR PROMAX FILIAL CRUZ'!T12," ") -> 304.13 | Q18: =IF(A18<0,'CAR PROMAX FILIAL CRUZ'!U12," ") -> 341.33 | R18: =IF(A18<0,'CAR PROMAX FILIAL CRUZ'!V12," ") -> 3612008105
A19: ='CAR PROMAX FILIAL CRUZ'!O13 -> -35 | B19: =IF(K19<0,IF(K19>-31,"INAD.",IF(K19>-76,"IREC.","PDD"))," ") -> IREC. | C19: =IF(K19<0,IF(K19>-16,"RN",IF(K19>-46,"GV","GC"))," ") -> GV | D19: =IF(A19<0,'CAR PROMAX FILIAL CRUZ'!B13," ") -> 3055 | E19: =IF(A19<0,'CAR PROMAX FILIAL CRUZ'!C13," ") -> Buteco dos amigos | F19: =IF(A19<0,'CAR PROMAX FILIAL CRUZ'!D13," ") -> 2 | G19: =IF(A19<0,'CAR PROMAX FILIAL CRUZ'!E13," ") -> 89621 | H19: =IF(A19<0,'CAR PROMAX FILIAL CRUZ'!J13," ") -> 514 | I19: =_xlfn.XLOOKUP(H19,'RN - SETORES'!A:A,'RN - SETORES'!B:B) -> Juan | J19: =_xlfn.XLOOKUP(C19,'GV - SETORES'!D:D,'GV - SETORES'!E:E,IF(K19>=-45,_xlfn.XLOOKUP(H19,'GV - SETORES'!A:A,'GV - SETORES'!B:B))) -> Jaissa | K19: =IF(A19<0,'CAR PROMAX FILIAL CRUZ'!O13," ") -> -35 | L19: =IF(A19<0,'CAR PROMAX FILIAL CRUZ'!P13," ") -> 46093 | M19: =IF(A19<0,'CAR PROMAX FILIAL CRUZ'!Q13," ") -> 46094 | N19: =IF(A19<0,'CAR PROMAX FILIAL CRUZ'!R13," ") -> 46101 | O19: =IF(A19<0,'CAR PROMAX FILIAL CRUZ'!S13," ") -> 622.85 | P19: =IF(A19<0,'CAR PROMAX FILIAL CRUZ'!T13," ") -> 622.85 | Q19: =IF(A19<0,'CAR PROMAX FILIAL CRUZ'!U13," ") -> 689.69 | R19: =IF(A19<0,'CAR PROMAX FILIAL CRUZ'!V13," ") -> 3612008353
... A36: ='CAR PROMAX FILIAL CRUZ'!O30 -> -1 | B36: =IF(K36<0,IF(K36>-31,"INAD.",IF(K36>-76,"IREC.","PDD"))," ") -> INAD. | C36: =IF(K36<0,IF(K36>-16,"RN",IF(K36>-46,"GV","GC"))," ") -> RN | D36: =IF(A36<0,'CAR PROMAX FILIAL CRUZ'!B30," ") -> 3459 | E36: =IF(A36<0,'CAR PROMAX FILIAL CRUZ'!C30," ") -> MERCADINHO MINI PREC | F36: =IF(A36<0,'CAR PROMAX FILIAL CRUZ'!D30," ") -> 2 | G36: =IF(A36<0,'CAR PROMAX FILIAL CRUZ'!E30," ") -> 95096 | H36: =IF(A36<0,'CAR PROMAX FILIAL CRUZ'!J30," ") -> 104 | I36: =_xlfn.XLOOKUP(H36,'RN - SETORES'!A:A,'RN - SETORES'!B:B) -> Neto | J36: =_xlfn.XLOOKUP(C36,'GV - SETORES'!D:D,'GV - SETORES'!E:E,IF(K36>=-45,_xlfn.XLOOKUP(H36,'GV - SETORES'!A:A,'GV - SETORES'!B:B))) -> Fredson | K36: =IF(A36<0,'CAR PROMAX FILIAL CRUZ'!O30," ") -> -1 | L36: =IF(A36<0,'CAR PROMAX FILIAL CRUZ'!P30," ") -> 46127 | M36: =IF(A36<0,'CAR PROMAX FILIAL CRUZ'!Q30," ") -> 46128 | N36: =IF(A36<0,'CAR PROMAX FILIAL CRUZ'!R30," ") -> 46135 | O36: =IF(A36<0,'CAR PROMAX FILIAL CRUZ'!S30," ") -> 336.22 | P36: =IF(A36<0,'CAR PROMAX FILIAL CRUZ'!T30," ") -> 336.22 | Q36: =IF(A36<0,'CAR PROMAX FILIAL CRUZ'!U30," ") -> 353.25 | R36: =IF(A36<0,'CAR PROMAX FILIAL CRUZ'!V30," ") -> 3612009142
A37: ='CAR PROMAX FILIAL CRUZ'!O31 -> 0 | B37: =IF(K37<0,IF(K37>-31,"INAD.",IF(K37>-76,"IREC.","PDD"))," ") | C37: =IF(K37<0,IF(K37>-16,"RN",IF(K37>-46,"GV","GC"))," ") | D37: =IF(A37<0,'CAR PROMAX FILIAL CRUZ'!B31," ") | E37: =IF(A37<0,'CAR PROMAX FILIAL CRUZ'!C31," ") | F37: =IF(A37<0,'CAR PROMAX FILIAL CRUZ'!D31," ") | G37: =IF(A37<0,'CAR PROMAX FILIAL CRUZ'!E31," ") | H37: =IF(A37<0,'CAR PROMAX FILIAL CRUZ'!J31," ") | K37: =IF(A37<0,'CAR PROMAX FILIAL CRUZ'!O31," ") | L37: =IF(A37<0,'CAR PROMAX FILIAL CRUZ'!P31," ") | M37: =IF(A37<0,'CAR PROMAX FILIAL CRUZ'!Q31," ") | N37: =IF(A37<0,'CAR PROMAX FILIAL CRUZ'!R31," ") | O37: =IF(A37<0,'CAR PROMAX FILIAL CRUZ'!S31," ") | P37: =IF(A37<0,'CAR PROMAX FILIAL CRUZ'!T31," ") | Q37: =IF(A37<0,'CAR PROMAX FILIAL CRUZ'!U31," ") | R37: =IF(A37<0,'CAR PROMAX FILIAL CRUZ'!V31," ")
A38: ='CAR PROMAX FILIAL CRUZ'!O32 -> 0 | B38: =IF(K38<0,IF(K38>-31,"INAD.",IF(K38>-76,"IREC.","PDD"))," ") | C38: =IF(K38<0,IF(K38>-16,"RN",IF(K38>-46,"GV","GC"))," ") | D38: =IF(A38<0,'CAR PROMAX FILIAL CRUZ'!B32," ") | E38: =IF(A38<0,'CAR PROMAX FILIAL CRUZ'!C32," ") | F38: =IF(A38<0,'CAR PROMAX FILIAL CRUZ'!D32," ") | G38: =IF(A38<0,'CAR PROMAX FILIAL CRUZ'!E32," ") | H38: =IF(A38<0,'CAR PROMAX FILIAL CRUZ'!J32," ") | K38: =IF(A38<0,'CAR PROMAX FILIAL CRUZ'!O32," ") | L38: =IF(A38<0,'CAR PROMAX FILIAL CRUZ'!P32," ") | M38: =IF(A38<0,'CAR PROMAX FILIAL CRUZ'!Q32," ") | N38: =IF(A38<0,'CAR PROMAX FILIAL CRUZ'!R32," ") | O38: =IF(A38<0,'CAR PROMAX FILIAL CRUZ'!S32," ") | P38: =IF(A38<0,'CAR PROMAX FILIAL CRUZ'!T32," ") | Q38: =IF(A38<0,'CAR PROMAX FILIAL CRUZ'!U32," ") | R38: =IF(A38<0,'CAR PROMAX FILIAL CRUZ'!V32," ")
A39: ='CAR PROMAX FILIAL CRUZ'!O33 -> 0 | B39: =IF(K39<0,IF(K39>-31,"INAD.",IF(K39>-76,"IREC.","PDD"))," ") | C39: =IF(K39<0,IF(K39>-16,"RN",IF(K39>-46,"GV","GC"))," ") | D39: =IF(A39<0,'CAR PROMAX FILIAL CRUZ'!B33," ") | E39: =IF(A39<0,'CAR PROMAX FILIAL CRUZ'!C33," ") | F39: =IF(A39<0,'CAR PROMAX FILIAL CRUZ'!D33," ") | G39: =IF(A39<0,'CAR PROMAX FILIAL CRUZ'!E33," ") | H39: =IF(A39<0,'CAR PROMAX FILIAL CRUZ'!J33," ") | K39: =IF(A39<0,'CAR PROMAX FILIAL CRUZ'!O33," ") | L39: =IF(A39<0,'CAR PROMAX FILIAL CRUZ'!P33," ") | M39: =IF(A39<0,'CAR PROMAX FILIAL CRUZ'!Q33," ") | N39: =IF(A39<0,'CAR PROMAX FILIAL CRUZ'!R33," ") | O39: =IF(A39<0,'CAR PROMAX FILIAL CRUZ'!S33," ") | P39: =IF(A39<0,'CAR PROMAX FILIAL CRUZ'!T33," ") | Q39: =IF(A39<0,'CAR PROMAX FILIAL CRUZ'!U33," ") | R39: =IF(A39<0,'CAR PROMAX FILIAL CRUZ'!V33," ")
A40: ='CAR PROMAX FILIAL CRUZ'!O34 -> 0 | B40: =IF(K40<0,IF(K40>-31,"INAD.",IF(K40>-76,"IREC.","PDD"))," ") | C40: =IF(K40<0,IF(K40>-16,"RN",IF(K40>-46,"GV","GC"))," ") | D40: =IF(A40<0,'CAR PROMAX FILIAL CRUZ'!B34," ") | E40: =IF(A40<0,'CAR PROMAX FILIAL CRUZ'!C34," ") | F40: =IF(A40<0,'CAR PROMAX FILIAL CRUZ'!D34," ") | G40: =IF(A40<0,'CAR PROMAX FILIAL CRUZ'!E34," ") | H40: =IF(A40<0,'CAR PROMAX FILIAL CRUZ'!J34," ") | K40: =IF(A40<0,'CAR PROMAX FILIAL CRUZ'!O34," ") | L40: =IF(A40<0,'CAR PROMAX FILIAL CRUZ'!P34," ") | M40: =IF(A40<0,'CAR PROMAX FILIAL CRUZ'!Q34," ") | N40: =IF(A40<0,'CAR PROMAX FILIAL CRUZ'!R34," ") | O40: =IF(A40<0,'CAR PROMAX FILIAL CRUZ'!S34," ") | P40: =IF(A40<0,'CAR PROMAX FILIAL CRUZ'!T34," ") | Q40: =IF(A40<0,'CAR PROMAX FILIAL CRUZ'!U34," ") | R40: =IF(A40<0,'CAR PROMAX FILIAL CRUZ'!V34," ")
A41: ='CAR PROMAX FILIAL CRUZ'!O35 -> 0 | B41: =IF(K41<0,IF(K41>-31,"INAD.",IF(K41>-76,"IREC.","PDD"))," ") | C41: =IF(K41<0,IF(K41>-16,"RN",IF(K41>-46,"GV","GC"))," ") | D41: =IF(A41<0,'CAR PROMAX FILIAL CRUZ'!B35," ") | E41: =IF(A41<0,'CAR PROMAX FILIAL CRUZ'!C35," ") | F41: =IF(A41<0,'CAR PROMAX FILIAL CRUZ'!D35," ") | G41: =IF(A41<0,'CAR PROMAX FILIAL CRUZ'!E35," ") | H41: =IF(A41<0,'CAR PROMAX FILIAL CRUZ'!J35," ") | K41: =IF(A41<0,'CAR PROMAX FILIAL CRUZ'!O35," ") | L41: =IF(A41<0,'CAR PROMAX FILIAL CRUZ'!P35," ") | M41: =IF(A41<0,'CAR PROMAX FILIAL CRUZ'!Q35," ") | N41: =IF(A41<0,'CAR PROMAX FILIAL CRUZ'!R35," ") | O41: =IF(A41<0,'CAR PROMAX FILIAL CRUZ'!S35," ") | P41: =IF(A41<0,'CAR PROMAX FILIAL CRUZ'!T35," ") | Q41: =IF(A41<0,'CAR PROMAX FILIAL CRUZ'!U35," ") | R41: =IF(A41<0,'CAR PROMAX FILIAL CRUZ'!V35," ")
A42: ='CAR PROMAX FILIAL CRUZ'!O36 -> 0 | B42: =IF(K42<0,IF(K42>-31,"INAD.",IF(K42>-76,"IREC.","PDD"))," ") | C42: =IF(K42<0,IF(K42>-16,"RN",IF(K42>-46,"GV","GC"))," ") | D42: =IF(A42<0,'CAR PROMAX FILIAL CRUZ'!B36," ") | E42: =IF(A42<0,'CAR PROMAX FILIAL CRUZ'!C36," ") | F42: =IF(A42<0,'CAR PROMAX FILIAL CRUZ'!D36," ") | G42: =IF(A42<0,'CAR PROMAX FILIAL CRUZ'!E36," ") | H42: =IF(A42<0,'CAR PROMAX FILIAL CRUZ'!J36," ") | K42: =IF(A42<0,'CAR PROMAX FILIAL CRUZ'!O36," ") | L42: =IF(A42<0,'CAR PROMAX FILIAL CRUZ'!P36," ") | M42: =IF(A42<0,'CAR PROMAX FILIAL CRUZ'!Q36," ") | N42: =IF(A42<0,'CAR PROMAX FILIAL CRUZ'!R36," ") | O42: =IF(A42<0,'CAR PROMAX FILIAL CRUZ'!S36," ") | P42: =IF(A42<0,'CAR PROMAX FILIAL CRUZ'!T36," ") | Q42: =IF(A42<0,'CAR PROMAX FILIAL CRUZ'!U36," ") | R42: =IF(A42<0,'CAR PROMAX FILIAL CRUZ'!V36," ")
A43: ='CAR PROMAX FILIAL CRUZ'!O37 -> 0 | B43: =IF(K43<0,IF(K43>-31,"INAD.",IF(K43>-76,"IREC.","PDD"))," ") | C43: =IF(K43<0,IF(K43>-16,"RN",IF(K43>-46,"GV","GC"))," ") | D43: =IF(A43<0,'CAR PROMAX FILIAL CRUZ'!B37," ") | E43: =IF(A43<0,'CAR PROMAX FILIAL CRUZ'!C37," ") | F43: =IF(A43<0,'CAR PROMAX FILIAL CRUZ'!D37," ") | G43: =IF(A43<0,'CAR PROMAX FILIAL CRUZ'!E37," ") | H43: =IF(A43<0,'CAR PROMAX FILIAL CRUZ'!J37," ") | K43: =IF(A43<0,'CAR PROMAX FILIAL CRUZ'!O37," ") | L43: =IF(A43<0,'CAR PROMAX FILIAL CRUZ'!P37," ") | M43: =IF(A43<0,'CAR PROMAX FILIAL CRUZ'!Q37," ") | N43: =IF(A43<0,'CAR PROMAX FILIAL CRUZ'!R37," ") | O43: =IF(A43<0,'CAR PROMAX FILIAL CRUZ'!S37," ") | P43: =IF(A43<0,'CAR PROMAX FILIAL CRUZ'!T37," ") | Q43: =IF(A43<0,'CAR PROMAX FILIAL CRUZ'!U37," ") | R43: =IF(A43<0,'CAR PROMAX FILIAL CRUZ'!V37," ")
A44: ='CAR PROMAX FILIAL CRUZ'!O38 -> 0 | B44: =IF(K44<0,IF(K44>-31,"INAD.",IF(K44>-76,"IREC.","PDD"))," ") | C44: =IF(K44<0,IF(K44>-16,"RN",IF(K44>-46,"GV","GC"))," ") | D44: =IF(A44<0,'CAR PROMAX FILIAL CRUZ'!B38," ") | E44: =IF(A44<0,'CAR PROMAX FILIAL CRUZ'!C38," ") | F44: =IF(A44<0,'CAR PROMAX FILIAL CRUZ'!D38," ") | G44: =IF(A44<0,'CAR PROMAX FILIAL CRUZ'!E38," ") | H44: =IF(A44<0,'CAR PROMAX FILIAL CRUZ'!J38," ") | K44: =IF(A44<0,'CAR PROMAX FILIAL CRUZ'!O38," ") | L44: =IF(A44<0,'CAR PROMAX FILIAL CRUZ'!P38," ") | M44: =IF(A44<0,'CAR PROMAX FILIAL CRUZ'!Q38," ") | N44: =IF(A44<0,'CAR PROMAX FILIAL CRUZ'!R38," ") | O44: =IF(A44<0,'CAR PROMAX FILIAL CRUZ'!S38," ") | P44: =IF(A44<0,'CAR PROMAX FILIAL CRUZ'!T38," ") | Q44: =IF(A44<0,'CAR PROMAX FILIAL CRUZ'!U38," ") | R44: =IF(A44<0,'CAR PROMAX FILIAL CRUZ'!V38," ")
A45: ='CAR PROMAX FILIAL CRUZ'!O39 -> 0 | B45: =IF(K45<0,IF(K45>-31,"INAD.",IF(K45>-76,"IREC.","PDD"))," ") | C45: =IF(K45<0,IF(K45>-16,"RN",IF(K45>-46,"GV","GC"))," ") | D45: =IF(A45<0,'CAR PROMAX FILIAL CRUZ'!B39," ") | E45: =IF(A45<0,'CAR PROMAX FILIAL CRUZ'!C39," ") | F45: =IF(A45<0,'CAR PROMAX FILIAL CRUZ'!D39," ") | G45: =IF(A45<0,'CAR PROMAX FILIAL CRUZ'!E39," ") | H45: =IF(A45<0,'CAR PROMAX FILIAL CRUZ'!J39," ") | K45: =IF(A45<0,'CAR PROMAX FILIAL CRUZ'!O39," ") | L45: =IF(A45<0,'CAR PROMAX FILIAL CRUZ'!P39," ") | M45: =IF(A45<0,'CAR PROMAX FILIAL CRUZ'!Q39," ") | N45: =IF(A45<0,'CAR PROMAX FILIAL CRUZ'!R39," ") | O45: =IF(A45<0,'CAR PROMAX FILIAL CRUZ'!S39," ") | P45: =IF(A45<0,'CAR PROMAX FILIAL CRUZ'!T39," ") | Q45: =IF(A45<0,'CAR PROMAX FILIAL CRUZ'!U39," ") | R45: =IF(A45<0,'CAR PROMAX FILIAL CRUZ'!V39," ")
A46: ='CAR PROMAX FILIAL CRUZ'!O40 -> 0 | B46: =IF(K46<0,IF(K46>-31,"INAD.",IF(K46>-76,"IREC.","PDD"))," ") | C46: =IF(K46<0,IF(K46>-16,"RN",IF(K46>-46,"GV","GC"))," ") | D46: =IF(A46<0,'CAR PROMAX FILIAL CRUZ'!B40," ") | E46: =IF(A46<0,'CAR PROMAX FILIAL CRUZ'!C40," ") | F46: =IF(A46<0,'CAR PROMAX FILIAL CRUZ'!D40," ") | G46: =IF(A46<0,'CAR PROMAX FILIAL CRUZ'!E40," ") | H46: =IF(A46<0,'CAR PROMAX FILIAL CRUZ'!J40," ") | K46: =IF(A46<0,'CAR PROMAX FILIAL CRUZ'!O40," ") | L46: =IF(A46<0,'CAR PROMAX FILIAL CRUZ'!P40," ") | M46: =IF(A46<0,'CAR PROMAX FILIAL CRUZ'!Q40," ") | N46: =IF(A46<0,'CAR PROMAX FILIAL CRUZ'!R40," ") | O46: =IF(A46<0,'CAR PROMAX FILIAL CRUZ'!S40," ") | P46: =IF(A46<0,'CAR PROMAX FILIAL CRUZ'!T40," ") | Q46: =IF(A46<0,'CAR PROMAX FILIAL CRUZ'!U40," ") | R46: =IF(A46<0,'CAR PROMAX FILIAL CRUZ'!V40," ")
A47: ='CAR PROMAX FILIAL CRUZ'!O41 -> 0 | B47: =IF(K47<0,IF(K47>-31,"INAD.",IF(K47>-76,"IREC.","PDD"))," ") | C47: =IF(K47<0,IF(K47>-16,"RN",IF(K47>-46,"GV","GC"))," ") | D47: =IF(A47<0,'CAR PROMAX FILIAL CRUZ'!B41," ") | E47: =IF(A47<0,'CAR PROMAX FILIAL CRUZ'!C41," ") | F47: =IF(A47<0,'CAR PROMAX FILIAL CRUZ'!D41," ") | G47: =IF(A47<0,'CAR PROMAX FILIAL CRUZ'!E41," ") | H47: =IF(A47<0,'CAR PROMAX FILIAL CRUZ'!J41," ") | K47: =IF(A47<0,'CAR PROMAX FILIAL CRUZ'!O41," ") | L47: =IF(A47<0,'CAR PROMAX FILIAL CRUZ'!P41," ") | M47: =IF(A47<0,'CAR PROMAX FILIAL CRUZ'!Q41," ") | N47: =IF(A47<0,'CAR PROMAX FILIAL CRUZ'!R41," ") | O47: =IF(A47<0,'CAR PROMAX FILIAL CRUZ'!S41," ") | P47: =IF(A47<0,'CAR PROMAX FILIAL CRUZ'!T41," ") | Q47: =IF(A47<0,'CAR PROMAX FILIAL CRUZ'!U41," ") | R47: =IF(A47<0,'CAR PROMAX FILIAL CRUZ'!V41," ")
A48: ='CAR PROMAX FILIAL CRUZ'!O42 -> 0 | B48: =IF(K48<0,IF(K48>-31,"INAD.",IF(K48>-76,"IREC.","PDD"))," ") | C48: =IF(K48<0,IF(K48>-16,"RN",IF(K48>-46,"GV","GC"))," ") | D48: =IF(A48<0,'CAR PROMAX FILIAL CRUZ'!B42," ") | E48: =IF(A48<0,'CAR PROMAX FILIAL CRUZ'!C42," ") | F48: =IF(A48<0,'CAR PROMAX FILIAL CRUZ'!D42," ") | G48: =IF(A48<0,'CAR PROMAX FILIAL CRUZ'!E42," ") | H48: =IF(A48<0,'CAR PROMAX FILIAL CRUZ'!J42," ") | K48: =IF(A48<0,'CAR PROMAX FILIAL CRUZ'!O42," ") | L48: =IF(A48<0,'CAR PROMAX FILIAL CRUZ'!P42," ") | M48: =IF(A48<0,'CAR PROMAX FILIAL CRUZ'!Q42," ") | N48: =IF(A48<0,'CAR PROMAX FILIAL CRUZ'!R42," ") | O48: =IF(A48<0,'CAR PROMAX FILIAL CRUZ'!S42," ") | P48: =IF(A48<0,'CAR PROMAX FILIAL CRUZ'!T42," ") | Q48: =IF(A48<0,'CAR PROMAX FILIAL CRUZ'!U42," ") | R48: =IF(A48<0,'CAR PROMAX FILIAL CRUZ'!V42," ")
... A77: ='CAR PROMAX FILIAL CRUZ'!O71 -> 3 | B77: =IF(K77<0,IF(K77>-31,"INAD.",IF(K77>-76,"IREC.","PDD"))," ") | C77: =IF(K77<0,IF(K77>-16,"RN",IF(K77>-46,"GV","GC"))," ") | D77: =IF(A77<0,'CAR PROMAX FILIAL CRUZ'!B71," ") | E77: =IF(A77<0,'CAR PROMAX FILIAL CRUZ'!C71," ") | F77: =IF(A77<0,'CAR PROMAX FILIAL CRUZ'!D71," ") | G77: =IF(A77<0,'CAR PROMAX FILIAL CRUZ'!E71," ") | H77: =IF(A77<0,'CAR PROMAX FILIAL CRUZ'!J71," ") | K77: =IF(A77<0,'CAR PROMAX FILIAL CRUZ'!O71," ") | L77: =IF(A77<0,'CAR PROMAX FILIAL CRUZ'!P71," ") | M77: =IF(A77<0,'CAR PROMAX FILIAL CRUZ'!Q71," ") | N77: =IF(A77<0,'CAR PROMAX FILIAL CRUZ'!R71," ") | O77: =IF(A77<0,'CAR PROMAX FILIAL CRUZ'!S71," ") | P77: =IF(A77<0,'CAR PROMAX FILIAL CRUZ'!T71," ") | Q77: =IF(A77<0,'CAR PROMAX FILIAL CRUZ'!U71," ") | R77: =IF(A77<0,'CAR PROMAX FILIAL CRUZ'!V71," ")
A78: ='CAR PROMAX FILIAL CRUZ'!O72 -> 3 | B78: =IF(K78<0,IF(K78>-31,"INAD.",IF(K78>-75,"IREC.","PDD"))," ") | C78: =IF(K78<0,IF(K78>-16,"RN",IF(K78>-46,"GV","GC"))," ") | D78: =IF(A78<0,'CAR PROMAX FILIAL CRUZ'!B72," ") | E78: =IF(A78<0,'CAR PROMAX FILIAL CRUZ'!C72," ") | F78: =IF(A78<0,'CAR PROMAX FILIAL CRUZ'!D72," ") | G78: =IF(A78<0,'CAR PROMAX FILIAL CRUZ'!E72," ") | H78: =IF(A78<0,'CAR PROMAX FILIAL CRUZ'!J72," ") | K78: =IF(A78<0,'CAR PROMAX FILIAL CRUZ'!O72," ") | L78: =IF(A78<0,'CAR PROMAX FILIAL CRUZ'!P72," ") | M78: =IF(A78<0,'CAR PROMAX FILIAL CRUZ'!Q72," ") | N78: =IF(A78<0,'CAR PROMAX FILIAL CRUZ'!R72," ") | O78: =IF(A78<0,'CAR PROMAX FILIAL CRUZ'!S72," ") | P78: =IF(A78<0,'CAR PROMAX FILIAL CRUZ'!T72," ") | Q78: =IF(A78<0,'CAR PROMAX FILIAL CRUZ'!U72," ") | R78: =IF(A78<0,'CAR PROMAX FILIAL CRUZ'!V72," ")
A79: ='CAR PROMAX FILIAL CRUZ'!O73 -> 3 | B79: =IF(K79<0,IF(K79>-31,"INAD.",IF(K79>-75,"IREC.","PDD"))," ") | C79: =IF(K79<0,IF(K79>-16,"RN",IF(K79>-46,"GV","GC"))," ") | D79: =IF(A79<0,'CAR PROMAX FILIAL CRUZ'!B73," ") | E79: =IF(A79<0,'CAR PROMAX FILIAL CRUZ'!C73," ") | F79: =IF(A79<0,'CAR PROMAX FILIAL CRUZ'!D73," ") | G79: =IF(A79<0,'CAR PROMAX FILIAL CRUZ'!E73," ") | H79: =IF(A79<0,'CAR PROMAX FILIAL CRUZ'!J73," ") | K79: =IF(A79<0,'CAR PROMAX FILIAL CRUZ'!O73," ") | L79: =IF(A79<0,'CAR PROMAX FILIAL CRUZ'!P73," ") | M79: =IF(A79<0,'CAR PROMAX FILIAL CRUZ'!Q73," ") | N79: =IF(A79<0,'CAR PROMAX FILIAL CRUZ'!R73," ") | O79: =IF(A79<0,'CAR PROMAX FILIAL CRUZ'!S73," ") | P79: =IF(A79<0,'CAR PROMAX FILIAL CRUZ'!T73," ") | Q79: =IF(A79<0,'CAR PROMAX FILIAL CRUZ'!U73," ") | R79: =IF(A79<0,'CAR PROMAX FILIAL CRUZ'!V73," ")
A80: ='CAR PROMAX FILIAL CRUZ'!O74 -> 3 | B80: =IF(K80<0,IF(K80>-31,"INAD.",IF(K80>-75,"IREC.","PDD"))," ") | C80: =IF(K80<0,IF(K80>-16,"RN",IF(K80>-46,"GV","GC"))," ") | D80: =IF(A80<0,'CAR PROMAX FILIAL CRUZ'!B74," ") | E80: =IF(A80<0,'CAR PROMAX FILIAL CRUZ'!C74," ") | F80: =IF(A80<0,'CAR PROMAX FILIAL CRUZ'!D74," ") | G80: =IF(A80<0,'CAR PROMAX FILIAL CRUZ'!E74," ") | H80: =IF(A80<0,'CAR PROMAX FILIAL CRUZ'!J74," ") | K80: =IF(A80<0,'CAR PROMAX FILIAL CRUZ'!O74," ") | L80: =IF(A80<0,'CAR PROMAX FILIAL CRUZ'!P74," ") | M80: =IF(A80<0,'CAR PROMAX FILIAL CRUZ'!Q74," ") | N80: =IF(A80<0,'CAR PROMAX FILIAL CRUZ'!R74," ") | O80: =IF(A80<0,'CAR PROMAX FILIAL CRUZ'!S74," ") | P80: =IF(A80<0,'CAR PROMAX FILIAL CRUZ'!T74," ") | Q80: =IF(A80<0,'CAR PROMAX FILIAL CRUZ'!U74," ") | R80: =IF(A80<0,'CAR PROMAX FILIAL CRUZ'!V74," ")
A81: ='CAR PROMAX FILIAL CRUZ'!O75 -> 3 | B81: =IF(K81<0,IF(K81>-31,"INAD.",IF(K81>-75,"IREC.","PDD"))," ") | C81: =IF(K81<0,IF(K81>-16,"RN",IF(K81>-46,"GV","GC"))," ") | D81: =IF(A81<0,'CAR PROMAX FILIAL CRUZ'!B75," ") | E81: =IF(A81<0,'CAR PROMAX FILIAL CRUZ'!C75," ") | F81: =IF(A81<0,'CAR PROMAX FILIAL CRUZ'!D75," ") | G81: =IF(A81<0,'CAR PROMAX FILIAL CRUZ'!E75," ") | H81: =IF(A81<0,'CAR PROMAX FILIAL CRUZ'!J75," ") | K81: =IF(A81<0,'CAR PROMAX FILIAL CRUZ'!O75," ") | L81: =IF(A81<0,'CAR PROMAX FILIAL CRUZ'!P75," ") | M81: =IF(A81<0,'CAR PROMAX FILIAL CRUZ'!Q75," ") | N81: =IF(A81<0,'CAR PROMAX FILIAL CRUZ'!R75," ") | O81: =IF(A81<0,'CAR PROMAX FILIAL CRUZ'!S75," ") | P81: =IF(A81<0,'CAR PROMAX FILIAL CRUZ'!T75," ") | Q81: =IF(A81<0,'CAR PROMAX FILIAL CRUZ'!U75," ") | R81: =IF(A81<0,'CAR PROMAX FILIAL CRUZ'!V75," ")
A82: ='CAR PROMAX FILIAL CRUZ'!O76 -> 3 | B82: =IF(K82<0,IF(K82>-31,"INAD.",IF(K82>-75,"IREC.","PDD"))," ") | C82: =IF(K82<0,IF(K82>-16,"RN",IF(K82>-46,"GV","GC"))," ") | D82: =IF(A82<0,'CAR PROMAX FILIAL CRUZ'!B76," ") | E82: =IF(A82<0,'CAR PROMAX FILIAL CRUZ'!C76," ") | F82: =IF(A82<0,'CAR PROMAX FILIAL CRUZ'!D76," ") | G82: =IF(A82<0,'CAR PROMAX FILIAL CRUZ'!E76," ") | H82: =IF(A82<0,'CAR PROMAX FILIAL CRUZ'!J76," ") | K82: =IF(A82<0,'CAR PROMAX FILIAL CRUZ'!O76," ") | L82: =IF(A82<0,'CAR PROMAX FILIAL CRUZ'!P76," ") | M82: =IF(A82<0,'CAR PROMAX FILIAL CRUZ'!Q76," ") | N82: =IF(A82<0,'CAR PROMAX FILIAL CRUZ'!R76," ") | O82: =IF(A82<0,'CAR PROMAX FILIAL CRUZ'!S76," ") | P82: =IF(A82<0,'CAR PROMAX FILIAL CRUZ'!T76," ") | Q82: =IF(A82<0,'CAR PROMAX FILIAL CRUZ'!U76," ") | R82: =IF(A82<0,'CAR PROMAX FILIAL CRUZ'!V76," ")
A83: ='CAR PROMAX FILIAL CRUZ'!O77 -> 3 | B83: =IF(K83<0,IF(K83>-31,"INAD.",IF(K83>-75,"IREC.","PDD"))," ") | C83: =IF(K83<0,IF(K83>-16,"RN",IF(K83>-46,"GV","GC"))," ") | D83: =IF(A83<0,'CAR PROMAX FILIAL CRUZ'!B77," ") | E83: =IF(A83<0,'CAR PROMAX FILIAL CRUZ'!C77," ") | F83: =IF(A83<0,'CAR PROMAX FILIAL CRUZ'!D77," ") | G83: =IF(A83<0,'CAR PROMAX FILIAL CRUZ'!E77," ") | H83: =IF(A83<0,'CAR PROMAX FILIAL CRUZ'!J77," ") | K83: =IF(A83<0,'CAR PROMAX FILIAL CRUZ'!O77," ") | L83: =IF(A83<0,'CAR PROMAX FILIAL CRUZ'!P77," ") | M83: =IF(A83<0,'CAR PROMAX FILIAL CRUZ'!Q77," ") | N83: =IF(A83<0,'CAR PROMAX FILIAL CRUZ'!R77," ") | O83: =IF(A83<0,'CAR PROMAX FILIAL CRUZ'!S77," ") | P83: =IF(A83<0,'CAR PROMAX FILIAL CRUZ'!T77," ") | Q83: =IF(A83<0,'CAR PROMAX FILIAL CRUZ'!U77," ") | R83: =IF(A83<0,'CAR PROMAX FILIAL CRUZ'!V77," ")
A84: ='CAR PROMAX FILIAL CRUZ'!O78 -> 3 | B84: =IF(K84<0,IF(K84>-31,"INAD.",IF(K84>-75,"IREC.","PDD"))," ") | C84: =IF(K84<0,IF(K84>-16,"RN",IF(K84>-46,"GV","GC"))," ") | D84: =IF(A84<0,'CAR PROMAX FILIAL CRUZ'!B78," ") | E84: =IF(A84<0,'CAR PROMAX FILIAL CRUZ'!C78," ") | F84: =IF(A84<0,'CAR PROMAX FILIAL CRUZ'!D78," ") | G84: =IF(A84<0,'CAR PROMAX FILIAL CRUZ'!E78," ") | H84: =IF(A84<0,'CAR PROMAX FILIAL CRUZ'!J78," ") | K84: =IF(A84<0,'CAR PROMAX FILIAL CRUZ'!O78," ") | L84: =IF(A84<0,'CAR PROMAX FILIAL CRUZ'!P78," ") | M84: =IF(A84<0,'CAR PROMAX FILIAL CRUZ'!Q78," ") | N84: =IF(A84<0,'CAR PROMAX FILIAL CRUZ'!R78," ") | O84: =IF(A84<0,'CAR PROMAX FILIAL CRUZ'!S78," ") | P84: =IF(A84<0,'CAR PROMAX FILIAL CRUZ'!T78," ") | Q84: =IF(A84<0,'CAR PROMAX FILIAL CRUZ'!U78," ") | R84: =IF(A84<0,'CAR PROMAX FILIAL CRUZ'!V78," ")
A85: ='CAR PROMAX FILIAL CRUZ'!O79 -> 3 | B85: =IF(K85<0,IF(K85>-31,"INAD.",IF(K85>-75,"IREC.","PDD"))," ") | C85: =IF(K85<0,IF(K85>-16,"RN",IF(K85>-46,"GV","GC"))," ") | D85: =IF(A85<0,'CAR PROMAX FILIAL CRUZ'!B79," ") | E85: =IF(A85<0,'CAR PROMAX FILIAL CRUZ'!C79," ") | F85: =IF(A85<0,'CAR PROMAX FILIAL CRUZ'!D79," ") | G85: =IF(A85<0,'CAR PROMAX FILIAL CRUZ'!E79," ") | H85: =IF(A85<0,'CAR PROMAX FILIAL CRUZ'!J79," ") | K85: =IF(A85<0,'CAR PROMAX FILIAL CRUZ'!O79," ") | L85: =IF(A85<0,'CAR PROMAX FILIAL CRUZ'!P79," ") | M85: =IF(A85<0,'CAR PROMAX FILIAL CRUZ'!Q79," ") | N85: =IF(A85<0,'CAR PROMAX FILIAL CRUZ'!R79," ") | O85: =IF(A85<0,'CAR PROMAX FILIAL CRUZ'!S79," ") | P85: =IF(A85<0,'CAR PROMAX FILIAL CRUZ'!T79," ") | Q85: =IF(A85<0,'CAR PROMAX FILIAL CRUZ'!U79," ") | R85: =IF(A85<0,'CAR PROMAX FILIAL CRUZ'!V79," ")
A86: ='CAR PROMAX FILIAL CRUZ'!O80 -> 3 | B86: =IF(K86<0,IF(K86>-31,"INAD.",IF(K86>-75,"IREC.","PDD"))," ") | C86: =IF(K86<0,IF(K86>-16,"RN",IF(K86>-46,"GV","GC"))," ") | D86: =IF(A86<0,'CAR PROMAX FILIAL CRUZ'!B80," ") | E86: =IF(A86<0,'CAR PROMAX FILIAL CRUZ'!C80," ") | F86: =IF(A86<0,'CAR PROMAX FILIAL CRUZ'!D80," ") | G86: =IF(A86<0,'CAR PROMAX FILIAL CRUZ'!E80," ") | H86: =IF(A86<0,'CAR PROMAX FILIAL CRUZ'!J80," ") | K86: =IF(A86<0,'CAR PROMAX FILIAL CRUZ'!O80," ") | L86: =IF(A86<0,'CAR PROMAX FILIAL CRUZ'!P80," ") | M86: =IF(A86<0,'CAR PROMAX FILIAL CRUZ'!Q80," ") | N86: =IF(A86<0,'CAR PROMAX FILIAL CRUZ'!R80," ") | O86: =IF(A86<0,'CAR PROMAX FILIAL CRUZ'!S80," ") | P86: =IF(A86<0,'CAR PROMAX FILIAL CRUZ'!T80," ") | Q86: =IF(A86<0,'CAR PROMAX FILIAL CRUZ'!U80," ") | R86: =IF(A86<0,'CAR PROMAX FILIAL CRUZ'!V80," ")
...

Sheet CAR PROMAX FILIAL CRUZ
A1: UNB | B1: Cliente | C1: Nome | D1: UNB | E1: Titulo | F1: Parcela | G1: GDD | H1: GteVendas | I1: Superv | J1: Vendedor | K1: Especie | L1: Vinculo | M1: Portador | N1: Indicador CA/PRZ | O1: Dias | P1: DataEmissao | Q1: DataEntrega | R1: DataVencto | S1: ValorOriginal | T1: ValorPendente | U1: ValorCorrigido | V1: Nr. Banco | W1: DV | X1: AGING | Z1: Nr. CV | AA1: Segmento | AB1: Classe de Risco Atual | AC1: Tipo Doc | AD1: Classe Risco Apurada | AE1: Título de Aluguel | AF1: Tipo Vale | AG1: Dt Negociação | AH1: Status da Cobrança | AI1: Usuário atendimento | AJ1: Histórico Último Atendimento | AK1: Título Logistica | AL1: Franquia | AM1: Id Venda a Vista
A2: 2 | B2: 576 | C2: ROCK VARIEDADES JUR | D2: 2 | E2: 79246 | F2: 0 | G2: 1 | H2: 1 | I2: 10 | J2: 101 | K2: 4 | L2: 0 | M2: 237 | O2: -95 | P2: 46034 | Q2: 46035 | R2: 46041 | S2: 459.85 | T2: 459.85 | U2: 555.18 | V2: 3612006755 | W2: 6 | X2: PDD 180 | Z2: 0 | AA2: 73 | AB2: 5 | AC2: T | AD2: 4 | AL2: N
A3: 2 | B3: 3730 | C3: GELADAO PREA | D3: 2 | E3: 79463 | F3: 0 | G3: 1 | H3: 5 | I3: 50 | J3: 514 | K3: 4 | L3: 0 | M3: 237 | O3: -93 | P3: 46035 | Q3: 46036 | R3: 46043 | S3: 631.69 | T3: 631.69 | U3: 760.55 | V3: 3612006784 | W3: P | X3: PDD 180 | Z3: 0 | AA3: 73 | AB3: 5 | AC3: T | AD3: 4 | AL3: N
A4: 2 | B4: 576 | C4: ROCK VARIEDADES JUR | D4: 2 | E4: 80550 | F4: 0 | G4: 1 | H4: 1 | I4: 10 | J4: 101 | K4: 4 | L4: 0 | M4: 237 | O4: -88 | P4: 46041 | Q4: 46042 | R4: 46048 | S4: 300.93 | T4: 300.93 | U4: 359.8 | V4: 3612006964 | W4: 8 | X4: PDD 180 | Z4: 0 | AA4: 73 | AB4: 5 | AC4: T | AD4: 4 | AL4: N
A5: 2 | B5: 253 | C5: PESQUE E PAGUE SAO J | D5: 2 | E5: 83008 | F5: 0 | G5: 1 | H5: 5 | I5: 50 | J5: 513 | K5: 4 | L5: 0 | M5: 237 | O5: -74 | P5: 46052 | Q5: 46053 | R5: 46062 | S5: 143.31 | T5: 143.31 | U5: 168 | V5: 3612007292 | W5: 4 | X5: PDD 180 | Z5: 0 | AA5: 75 | AB5: 5 | AC5: T | AD5: 3 | AG5: 46092 | AI5: Marlon Marques da Motta Mendes | AJ5: ACORDO PARCELAMENTO | AL5: N
A6: 2 | B6: 253 | C6: PESQUE E PAGUE SAO J | D6: 2 | E6: 83009 | F6: 0 | G6: 1 | H6: 5 | I6: 50 | J6: 513 | K6: 4 | L6: 0 | M6: 237 | O6: -74 | P6: 46052 | Q6: 46053 | R6: 46062 | S6: 883.83 | T6: 883.83 | U6: 1036.13 | V6: 3612007293 | W6: 2 | X6: PDD 180 | Z6: 0 | AA6: 75 | AB6: 5 | AC6: T | AD6: 3 | AG6: 46092 | AI6: Marlon Marques da Motta Mendes | AJ6: ACORDO PARCELAMENTO | AL6: N
A7: 2 | B7: 253 | C7: PESQUE E PAGUE SAO J | D7: 2 | E7: 84202 | F7: 0 | G7: 1 | H7: 5 | I7: 50 | J7: 513 | K7: 4 | L7: 0 | M7: 237 | O7: -67 | P7: 46059 | Q7: 46060 | R7: 46069 | S7: 827.03 | T7: 827.03 | U7: 959.9 | V7: 3612007481 | W7: 1 | X7: PDD MES | Z7: 0 | AA7: 75 | AB7: 5 | AC7: T | AD7: 4 | AG7: 46092 | AI7: Marlon Marques da Motta Mendes | AJ7: ACORDO PARCELAMENTO | AL7: N
A8: 2 | B8: 3898 | C8: ROTA DO SABOR | D8: 2 | E8: 85694 | F8: 0 | G8: 1 | H8: 1 | I8: 10 | J8: 104 | K8: 4 | L8: 0 | M8: 237 | O8: -65 | P8: 46066 | Q8: 46067 | R8: 46071 | S8: 213.61 | T8: 213.61 | U8: 247.21 | V8: 3612007713 | W8: 6 | X8: PDD MES | Z8: 0 | AA8: 75 | AB8: 5 | AC8: T | AD8: 4 | AL8: N
A9: 2 | B9: 3581 | C9: ADEGA BAR | D9: 2 | E9: 86353 | F9: 0 | G9: 1 | H9: 1 | I9: 10 | J9: 102 | K9: 4 | L9: 0 | M9: 237 | O9: -56 | P9: 46072 | Q9: 46073 | R9: 46080 | S9: 392.88 | T9: 392.88 | U9: 448.79 | V9: 3612007801 | W9: 9 | X9: PDD MES | Z9: 0 | AA9: 75 | AB9: 5 | AC9: T | AD9: 4 | AL9: N
A10: 2 | B10: 3581 | C10: ADEGA BAR | D10: 2 | E10: 86354 | F10: 0 | G10: 1 | H10: 1 | I10: 10 | J10: 102 | K10: 4 | L10: 0 | M10: 237 | O10: -56 | P10: 46072 | Q10: 46073 | R10: 46080 | S10: 509.94 | T10: 509.94 | U10: 582.51 | V10: 3612007802 | W10: 7 | X10: PDD MES | Z10: 0 | AA10: 75 | AB10: 5 | AC10: T | AD10: 4 | AL10: N
A11: 2 | B11: 2977 | C11: TRE CRAZY | D11: 2 | E11: 86678 | F11: 0 | G11: 1 | H11: 5 | I11: 50 | J11: 515 | K11: 4 | L11: 0 | M11: 237 | O11: -52 | P11: 46076 | Q11: 46077 | R11: 46084 | S11: 900.3 | T11: 900.3 | U11: 1022.43 | V11: 3612007844 | W11: 2 | X11: PDDIREC | Z11: 0 | AA11: 75 | AB11: 5 | AC11: T | AD11: 5 | AL11: N
A12: 2 | B12: 3322 | C12: PIZZARIA O ZEZINHO | D12: 2 | E12: 88274 | F12: 0 | G12: 1 | H12: 1 | I12: 10 | J12: 101 | K12: 4 | L12: 0 | M12: 237 | O12: -44 | P12: 46084 | Q12: 46085 | R12: 46092 | S12: 304.13 | T12: 304.13 | U12: 341.33 | V12: 3612008105 | W12: 2 | X12: PDDIREC | Z12: 0 | AA12: 75 | AB12: 4 | AC12: T | AD12: 4 | AL12: N
A13: 2 | B13: 3055 | C13: Buteco dos amigos | D13: 2 | E13: 89621 | F13: 0 | G13: 1 | H13: 5 | I13: 50 | J13: 514 | K13: 4 | L13: 0 | M13: 237 | O13: -35 | P13: 46093 | Q13: 46094 | R13: 46101 | S13: 622.85 | T13: 622.85 | U13: 689.69 | V13: 3612008353 | W13: 5 | X13: IREC | Z13: 0 | AA13: 75 | AB13: 5 | AC13: T | AD13: 5 | AL13: N
A14: 2 | B14: 3793 | C14: ORIGEM BAR | D14: 2 | E14: 89374 | F14: 0 | G14: 1 | H14: 5 | I14: 50 | J14: 514 | K14: 4 | L14: 0 | M14: 237 | O14: -35 | P14: 46092 | Q14: 46093 | R14: 46101 | S14: 1669.58 | T14: 1669.58 | U14: 1848.77 | V14: 3612008308 | W14: P | X14: IREC | Z14: 0 | AA14: 75 | AB14: 5 | AC14: T | AD14: 4 | AL14: N
A15: 2 | B15: 3968 | C15: REST. E PESTICARIA D | D15: 2 | E15: 89591 | F15: 0 | G15: 1 | H15: 5 | I15: 50 | J15: 514 | K15: 4 | L15: 0 | M15: 237 | O15: -35 | P15: 46093 | Q15: 46094 | R15: 46101 | S15: 894.24 | T15: 894.24 | U15: 990.21 | V15: 3612008348 | W15: 9 | X15: IREC | Z15: 0 | AA15: 75 | AB15: 4 | AC15: T | AD15: 3 | AL15: N
A16: 2 | B16: 3968 | C16: REST. E PESTICARIA D | D16: 2 | E16: 89907 | F16: 0 | G16: 1 | H16: 5 | I16: 50 | J16: 514 | K16: 4 | L16: 0 | M16: 237 | O16: -32 | P16: 46094 | Q16: 46095 | R16: 46104 | S16: 1225.24 | T16: 1225.24 | U16: 1350.61 | V16: 3612008405 | W16: 1 | X16: IREC | Z16: 0 | AA16: 75 | AB16: 4 | AC16: T | AD16: 3 | AL16: N
A17: 2 | B17: 2590 | C17: MULT STORE | D17: 2 | E17: 90478 | F17: 0 | G17: 1 | H17: 5 | I17: 50 | J17: 512 | K17: 4 | L17: 0 | M17: 237 | O17: -28 | P17: 46099 | Q17: 46101 | R17: 46108 | S17: 571.98 | T17: 571.98 | U17: 626.69 | V17: 3612008490 | W17: 6 | X17: IREC | Z17: 0 | AA17: 75 | AB17: 5 | AC17: T | AD17: 4 | AL17: N
A18: 2 | B18: 3345 | C18: S5 - BOTECO MARESIA | D18: 2 | E18: 93859 | F18: 0 | G18: 1 | H18: 5 | I18: 50 | J18: 514 | K18: 4 | L18: 0 | M18: 237 | O18: -7 | P18: 46121 | Q18: 46122 | R18: 46129 | S18: 949.69 | T18: 949.69 | U18: 1007.29 | V18: 3612008950 | W18: 9 | X18: Inadip Mes | Z18: 0 | AA18: 75 | AB18: 4 | AC18: T | AD18: 4 | AL18: N
A19: 2 | B19: 3994 | C19: CASA DO SABOR | D19: 2 | E19: 93940 | F19: 0 | G19: 1 | H19: 1 | I19: 10 | J19: 104 | K19: 4 | L19: 0 | M19: 237 | O19: -7 | P19: 46121 | Q19: 46122 | R19: 46129 | S19: 966.94 | T19: 966.94 | U19: 1025.6 | V19: 3612008965 | W19: 7 | X19: Inadip Mes | Z19: 0 | AA19: 75 | AB19: 4 | AC19: T | AD19: 4 | AL19: N
A20: 2 | B20: 427 | C20: SUP MERC ECONOMICO 0 | D20: 2 | E20: 94094 | F20: 0 | G20: 1 | H20: 5 | I20: 50 | J20: 515 | K20: 4 | L20: 0 | M20: 237 | O20: -4 | P20: 46122 | Q20: 46123 | R20: 46132 | S20: 3264.21 | T20: 3264.21 | U20: 3445.91 | V20: 3612008986 | W20: P | X20: Inadip Mes | Z20: 0 | AA20: 73 | AB20: 3 | AC20: T | AD20: 3 | AL20: N
A21: 2 | B21: 427 | C21: SUP MERC ECONOMICO 0 | D21: 2 | E21: 94095 | F21: 0 | G21: 1 | H21: 5 | I21: 50 | J21: 515 | K21: 4 | L21: 0 | M21: 237 | O21: -4 | P21: 46122 | Q21: 46123 | R21: 46132 | S21: 4072.78 | T21: 4072.78 | U21: 4299.49 | V21: 3612008987 | W21: 8 | X21: Inadip Mes | Z21: 0 | AA21: 73 | AB21: 3 | AC21: T | AD21: 3 | AL21: N
A22: 2 | B22: 3405 | C22: CLUBE DOS COQUEIROS | D22: 2 | E22: 94106 | F22: 0 | G22: 1 | H22: 5 | I22: 50 | J22: 511 | K22: 4 | L22: 0 | M22: 237 | O22: -4 | P22: 46122 | Q22: 46123 | R22: 46132 | S22: 663.4 | T22: 663.4 | U22: 700.32 | V22: 3612008990 | W22: 8 | X22: Inadip Mes | Z22: 0 | AA22: 73 | AB22: 4 | AC22: T | AD22: 4 | AL22: N
A23: 2 | B23: 3416 | C23: RESTAURANTE TIA ROSA | D23: 2 | E23: 94145 | F23: 0 | G23: 1 | H23: 1 | I23: 10 | J23: 104 | K23: 4 | L23: 0 | M23: 237 | O23: -4 | P23: 46122 | Q23: 46123 | R23: 46132 | S23: 304.93 | T23: 304.93 | U23: 321.9 | V23: 3612009001 | W23: 9 | X23: Inadip Mes | Z23: 0 | AA23: 75 | AB23: 5 | AC23: T | AD23: 5 | AL23: N
A24: 2 | B24: 265 | C24: STAR CONVENIENCIA A | D24: 2 | E24: 95102 | F24: 0 | G24: 1 | H24: 1 | I24: 10 | J24: 103 | K24: 4 | L24: 0 | M24: 237 | O24: -2 | P24: 46127 | Q24: 46128 | R24: 46134 | S24: 1663.39 | T24: 1663.39 | U24: 1750.43 | V24: 3612009147 | W24: 3 | X24: Inadip Mes | Z24: 0 | AA24: 73 | AB24: 3 | AC24: T | AD24: 3 | AL24: N
A25: 2 | B25: 1103 | C25: TN CONVENIENCIA JERI | D25: 2 | E25: 94719 | F25: 0 | G25: 1 | H25: 5 | I25: 50 | J25: 514 | K25: 4 | L25: 0 | M25: 237 | O25: -2 | P25: 46126 | Q25: 46127 | R25: 46134 | S25: 787.96 | T25: 787.96 | U25: 829.19 | V25: 3612009065 | W25: 5 | X25: Inadip Mes | Z25: 0 | AA25: 75 | AB25: 4 | AC25: T | AD25: 4 | AL25: N
A26: 2 | B26: 4006 | C26: MERCADINHO TODO DIA | D26: 2 | E26: 94815 | F26: 0 | G26: 1 | H26: 5 | I26: 50 | J26: 512 | K26: 4 | L26: 0 | M26: 237 | O26: -2 | P26: 46126 | Q26: 46127 | R26: 46134 | S26: 327 | T26: 327 | U26: 344.1 | V26: 3612009091 | W26: 4 | X26: Inadip Mes | Z26: 0 | AA26: 73 | AB26: 4 | AC26: T | AD26: 4 | AL26: N
A27: 2 | B27: 4024 | C27: MEGA FRIOS | D27: 2 | E27: 94702 | F27: 0 | G27: 1 | H27: 1 | I27: 10 | J27: 102 | K27: 4 | L27: 0 | M27: 237 | O27: -2 | P27: 46125 | Q27: 46126 | R27: 46134 | S27: 308.33 | T27: 308.33 | U27: 324.45 | V27: 3612009059 | W27: 0 | X27: Inadip Mes | Z27: 0 | AA27: 73 | AB27: 5 | AC27: T | AD27: 5 | AL27: N
A28: 2 | B28: 895 | C28: REST JERILICIA JERI | D28: 2 | E28: 95003 | F28: 0 | G28: 1 | H28: 5 | I28: 50 | J28: 514 | K28: 4 | L28: 0 | M28: 237 | O28: -1 | P28: 46127 | Q28: 46128 | R28: 46135 | S28: 320.16 | T28: 320.16 | U28: 336.37 | V28: 3612009125 | W28: 2 | X28: Inadip Mes | Z28: 0 | AA28: 75 | AB28: 4 | AC28: T | AD28: 4 | AL28: N
A29: 2 | B29: 2681 | C29: BUTECO DO ORLANDO 2 | D29: 2 | E29: 95028 | F29: 0 | G29: 1 | H29: 5 | I29: 50 | J29: 512 | K29: 4 | L29: 0 | M29: 237 | O29: -1 | P29: 46127 | Q29: 46128 | R29: 46135 | S29: 451.21 | T29: 451.21 | U29: 474.06 | V29: 3612009131 | W29: 7 | X29: Inadip Mes | Z29: 0 | AA29: 75 | AB29: 3 | AC29: T | AD29: 3 | AL29: N
A30: 2 | B30: 3459 | C30: MERCADINHO MINI PREC | D30: 2 | E30: 95096 | F30: 0 | G30: 1 | H30: 1 | I30: 10 | J30: 104 | K30: 4 | L30: 0 | M30: 237 | O30: -1 | P30: 46127 | Q30: 46128 | R30: 46135 | S30: 336.22 | T30: 336.22 | U30: 353.25 | V30: 3612009142 | W30: 2 | X30: Inadip Mes | Z30: 0 | AA30: 73 | AB30: 5 | AC30: T | AD30: 5 | AL30: N
A31: 2 | B31: 222 | C31: PADARIA SANTO EXPEDI | D31: 2 | E31: 96037 | F31: 0 | G31: 1 | H31: 1 | I31: 10 | J31: 102 | K31: 4 | L31: 0 | M31: 237 | O31: 0 | P31: 46132 | Q31: 46134 | R31: 46136 | S31: 343.45 | T31: 343.45 | U31: 343.45 | V31: 3612009270 | W31: 4 | Z31: 0 | AA31: 75 | AB31: 5 | AC31: T | AD31: 5 | AL31: N
A32: 2 | B32: 379 | C32: MERC.KELSO | D32: 2 | E32: 95374 | F32: 0 | G32: 1 | H32: 1 | I32: 10 | J32: 103 | K32: 4 | L32: 0 | M32: 237 | O32: 0 | P32: 46128 | Q32: 46129 | R32: 46136 | S32: 2870.98 | T32: 2870.98 | U32: 2870.98 | V32: 3612009185 | W32: 6 | Z32: 0 | AA32: 73 | AB32: 6 | AC32: T | AD32: 6 | AL32: N
A33: 2 | B33: 876 | C33: S5 - REST LUA CHEIA | D33: 2 | E33: 95264 | F33: 0 | G33: 1 | H33: 5 | I33: 50 | J33: 515 | K33: 4 | L33: 0 | M33: 237 | O33: 0 | P33: 46128 | Q33: 46129 | R33: 46136 | S33: 780.08 | T33: 780.08 | U33: 780.08 | V33: 3612009162 | W33: 7 | Z33: 0 | AA33: 75 | AB33: 6 | AC33: T | AD33: 6 | AL33: N
A34: 2 | B34: 925 | C34: LC. CONVENIENCIA DAS | D34: 2 | E34: 95318 | F34: 0 | G34: 1 | H34: 5 | I34: 50 | J34: 514 | K34: 4 | L34: 0 | M34: 237 | O34: 0 | P34: 46128 | Q34: 46129 | R34: 46136 | S34: 206.69 | T34: 206.69 | U34: 206.69 | V34: 3612009171 | W34: 6 | Z34: 0 | AA34: 75 | AB34: 3 | AC34: T | AD34: 3 | AL34: N
A35: 2 | B35: 986 | C35: CONVENIENCIA EMPORIO | D35: 2 | E35: 95308 | F35: 0 | G35: 1 | H35: 5 | I35: 50 | J35: 514 | K35: 4 | L35: 0 | M35: 237 | O35: 0 | P35: 46128 | Q35: 46129 | R35: 46136 | S35: 979.32 | T35: 979.32 | U35: 979.32 | V35: 3612009169 | W35: 4 | Z35: 0 | AA35: 73 | AB35: 3 | AC35: T | AD35: 3 | AL35: N
A36: 2 | B36: 2164 | C36: BAR DA NOVA | D36: 2 | E36: 95337 | F36: 0 | G36: 1 | H36: 1 | I36: 10 | J36: 104 | K36: 4 | L36: 0 | M36: 237 | O36: 0 | P36: 46128 | Q36: 46129 | R36: 46136 | S36: 218.86 | T36: 218.86 | U36: 218.86 | V36: 3612009177 | W36: 5 | Z36: 0 | AA36: 75 | AB36: 4 | AC36: T | AD36: 4 | AL36: N
A37: 2 | B37: 2164 | C37: BAR DA NOVA | D37: 2 | E37: 95338 | F37: 0 | G37: 1 | H37: 1 | I37: 10 | J37: 104 | K37: 4 | L37: 0 | M37: 237 | O37: 0 | P37: 46128 | Q37: 46129 | R37: 46136 | S37: 33.88 | T37: 33.88 | U37: 33.88 | V37: 3612009178 | W37: 3 | Z37: 0 | AA37: 75 | AB37: 4 | AC37: T | AD37: 4 | AL37: N
A38: 2 | B38: 2171 | C38: COMERCIAL GERSON | D38: 2 | E38: 95344 | F38: 0 | G38: 1 | H38: 1 | I38: 10 | J38: 104 | K38: 4 | L38: 0 | M38: 237 | O38: 0 | P38: 46128 | Q38: 46129 | R38: 46136 | S38: 766.13 | T38: 766.13 | U38: 766.13 | V38: 3612009183 | W38: P | Z38: 0 | AA38: 73 | AB38: 4 | AC38: T | AD38: 4 | AL38: N
A39: 2 | B39: 2261 | C39: C0MERCIAL ALBANIZA | D39: 2 | E39: 95330 | F39: 0 | G39: 1 | H39: 1 | I39: 10 | J39: 104 | K39: 4 | L39: 0 | M39: 237 | O39: 0 | P39: 46128 | Q39: 46129 | R39: 46136 | S39: 371.03 | T39: 371.03 | U39: 371.03 | V39: 3612009174 | W39: 0 | Z39: 0 | AA39: 73 | AB39: 3 | AC39: T | AD39: 3 | AL39: N
A40: 2 | B40: 2302 | C40: MERCADINHO CARNEIRO | D40: 2 | E40: 95410 | F40: 0 | G40: 1 | H40: 1 | I40: 10 | J40: 103 | K40: 4 | L40: 0 | M40: 237 | O40: 0 | P40: 46128 | Q40: 46129 | R40: 46136 | S40: 262.85 | T40: 262.85 | U40: 262.85 | V40: 3612009189 | W40: 9 | Z40: 0 | AA40: 73 | AB40: 6 | AC40: T | AD40: 6 | AL40: N
...

Sheet RANKING - GV
A1: TT VENCIDO => | B1: =SUM(B2:B4) -> 15820.3 | D1: GV
A2: R$ INAD. => | B2: =SUMIFS(MENU!O:O,MENU!B:B,"INAD.",MENU!K:K,">=-30",MENU!K:K,"<=0",MENU!J:J,'RANKING - GV'!D2) -> 11408.39 | D2: Jaissa
A3: R$ IREC. => | B3: =SUMIFS(MENU!O:O,MENU!B:B,"IREC.",MENU!K:K,">=-75",MENU!K:K,"<=0",MENU!J:J,'RANKING - GV'!D2) -> 4411.91
A4: R$ PDD => | B4: =SUMIFS(MENU!O:O, MENU!B:B, "PDD", MENU!K:K, "<=-75",MENU!J:J,'RANKING - GV'!D2) -> 0
A8: META | B8: PORCENTAGEM DE CADA GV
A9: 0.30% | B9: =$B$2/MENU!N2 -> 0.0028706744
A10: 0.12% | B10: =B3/MENU!N2 -> 0.0011101616

Sheet GV - SETORES
A1: SETORES | B1: GV | D1: GC | E1: Anderson
A2: 512 | B2: Jaissa
A3: 513 | B3: Jaissa
A4: 514 | B4: Jaissa
A5: 511 | B5: Jaissa
A6: 515 | B6: Jaissa
A7: 101 | B7: Fredson
A8: 103 | B8: Fredson
A9: 102 | B9: Fredson
A10: 104 | B10: Fredson
A11: 501 | B11: Fredson

Sheet RN - SETORES
A1: 106 | B1: Juan
A2: 103 | B2: André
A3: 101 | B3: Francisco Damilo
A4: 102 | B4: Francisco
A5: 104 | B5: Neto
A6: 512 | B6: =_xlfn.TEXTBEFORE(PROPER(_xlfn.XLOOKUP(A6,'[1]01.20.11_PW01127R_Lucas_v_11491'!$B:$B,'[1]01.20.11_PW01127R_Lucas_v_11491'!$C:$C))," ") -> Kelvia
A7: 513 | B7: =_xlfn.TEXTBEFORE(PROPER(_xlfn.XLOOKUP(A7,'[1]01.20.11_PW01127R_Lucas_v_11491'!$B:$B,'[1]01.20.11_PW01127R_Lucas_v_11491'!$C:$C))," ") -> Jefferson
A8: 514 | B8: =_xlfn.TEXTBEFORE(PROPER(_xlfn.XLOOKUP(A8,'[1]01.20.11_PW01127R_Lucas_v_11491'!$B:$B,'[1]01.20.11_PW01127R_Lucas_v_11491'!$C:$C))," ") -> Juan
A9: 515 | B9: =_xlfn.TEXTBEFORE(PROPER(_xlfn.XLOOKUP(A9,'[1]01.20.11_PW01127R_Lucas_v_11491'!$B:$B,'[1]01.20.11_PW01127R_Lucas_v_11491'!$C:$C))," ") -> Jose
A10: 511 | B10: Danilo
